Workbook
Name Slicer_Diabetes_Status: #N/A
Name Slicer_Weight_Status: #N/A

Sheet Hospitalisation Details
A1: Customer ID | B1: year | C1: month | D1: date | E1: children | F1: charges | G1: Hospital tier | H1: City tier | I1: State ID | J1: Impute Missing year | K1: Missing Month | L1: Hospital tier2 | M1: City tier2 | N1: State ID2 | O1: Customer ID2
A2: ? | B2: 2004 | C2: Nov | D2: 6 | E2: 0 | F2: 1137.01 | G2: tier - 3 | H2: tier - 1 | I2: R1013 | J2: =IF(B2="?",ROUND(AVERAGEIF($B$2:$B$2344,"<>?"),0),B2) -> 2004 | K2: =IF(C2="?","Sep",C2) -> Nov | L2: =IF(Table1[[#This Row],[Hospital tier]]="?","tier - 2",Table1[[#This Row],[Hospital tier]]) -> tier - 3 | M2: =IF(Table1[[#This Row],[City tier]]="?","tier - 2",Table1[[#This Row],[City tier]]) -> tier - 1 | N2: =IF(Table1[[#This Row],[State ID]]="?","Unknown",Table1[[#This Row],[State ID]]) -> R1013 | O2: =IF(Table1[[#This Row],[Customer ID]]="?","Unknown",Table1[[#This Row],[Customer ID]]) -> Unknown
A3: ? | B3: 1999 | C3: Jun | D3: 9 | E3: 1 | F3: 2775.19 | G3: tier - 2 | H3: tier - 1 | I3: R1012 | J3: =IF(B3="?",ROUND(AVERAGEIF($B$2:$B$2344,"<>?"),0),B3) -> 1999 | K3: =IF(C3="?","Sep",C3) -> Jun | L3: =IF(Table1[[#This Row],[Hospital tier]]="?","tier - 2",Table1[[#This Row],[Hospital tier]]) -> tier - 2 | M3: =IF(Table1[[#This Row],[City tier]]="?","tier - 2",Table1[[#This Row],[City tier]]) -> tier - 1 | N3: =IF(Table1[[#This Row],[State ID]]="?","Unknown",Table1[[#This Row],[State ID]]) -> R1012 | O3: =IF(Table1[[#This Row],[Customer ID]]="?","Unknown",Table1[[#This Row],[Customer ID]]) -> Unknown
A4: ? | B4: 1985 | C4: Dec | D4: 20 | E4: 2 | F4: 6203.9 | G4: tier - 1 | H4: tier - 2 | I4: R1012 | J4: =IF(B4="?",ROUND(AVERAGEIF($B$2:$B$2344,"<>?"),0),B4) -> 1985 | K4: =IF(C4="?","Sep",C4) -> Dec | L4: =IF(Table1[[#This Row],[Hospital tier]]="?","tier - 2",Table1[[#This Row],[Hospital tier]]) -> tier - 1 | M4: =IF(Table1[[#This Row],[City tier]]="?","tier - 2",Table1[[#This Row],[City tier]]) -> tier - 2 | N4: =IF(Table1[[#This Row],[State ID]]="?","Unknown",Table1[[#This Row],[State ID]]) -> R1012 | O4: =IF(Table1[[#This Row],[Customer ID]]="?","Unknown",Table1[[#This Row],[Customer ID]]) -> Unknown
A5: ? | B5: 2000 | C5: Oct | D5: 13 | E5: 0 | F5: 35585.58 | G5: tier - 1 | H5: tier - 2 | I5: R1011 | J5: =IF(B5="?",ROUND(AVERAGEIF($B$2:$B$2344,"<>?"),0),B5) -> 2000 | K5: =IF(C5="?","Sep",C5) -> Oct | L5: =IF(Table1[[#This Row],[Hospital tier]]="?","tier - 2",Table1[[#This Row],[Hospital tier]]) -> tier - 1 | M5: =IF(Table1[[#This Row],[City tier]]="?","tier - 2",Table1[[#This Row],[City tier]]) -> tier - 2 | N5: =IF(Table1[[#This Row],[State ID]]="?","Unknown",Table1[[#This Row],[State ID]]) -> R1011 | O5: =IF(Table1[[#This Row],[Customer ID]]="?","Unknown",Table1[[#This Row],[Customer ID]]) -> Unknown
A6: ? | B6: 1992 | C6: Oct | D6: 6 | E6: 0 | F6: 36837.47 | G6: tier - 1 | H6: tier - 2 | I6: R1011 | J6: =IF(B6="?",ROUND(AVERAGEIF($B$2:$B$2344,"<>?"),0),B6) -> 1992 | K6: =IF(C6="?","Sep",C6) -> Oct | L6: =IF(Table1[[#This Row],[Hospital tier]]="?","tier - 2",Table1[[#This Row],[Hospital tier]]) -> tier - 1 | M6: =IF(Table1[[#This Row],[City tier]]="?","tier - 2",Table1[[#This Row],[City tier]]) -> tier - 2 | N6: =IF(Table1[[#This Row],[State ID]]="?","Unknown",Table1[[#This Row],[State ID]]) -> R1011 | O6: =IF(Table1[[#This Row],[Customer ID]]="?","Unknown",Table1[[#This Row],[Customer ID]]) -> Unknown
A7: ? | B7: 1991 | C7: Nov | D7: 22 | E7: 2 | F7: 38711 | G7: tier - 1 | H7: tier - 3 | I7: R1011 | J7: =IF(B7="?",ROUND(AVERAGEIF($B$2:$B$2344,"<>?"),0),B7) -> 1991 | K7: =IF(C7="?","Sep",C7) -> Nov | L7: =IF(Table1[[#This Row],[Hospital tier]]="?","tier - 2",Table1[[#This Row],[Hospital tier]]) -> tier - 1 | M7: =IF(Table1[[#This Row],[City tier]]="?","tier - 2",Table1[[#This Row],[City tier]]) -> tier - 3 | N7: =IF(Table1[[#This Row],[State ID]]="?","Unknown",Table1[[#This Row],[State ID]]) -> R1011 | O7: =IF(Table1[[#This Row],[Customer ID]]="?","Unknown",Table1[[#This Row],[Customer ID]]) -> Unknown
A8: Id1 | B8: 1968 | C8: Oct | D8: 12 | E8: 0 | F8: 63770.43 | G8: tier - 1 | H8: tier - 3 | I8: R1013 | J8: =IF(B8="?",ROUND(AVERAGEIF($B$2:$B$2344,"<>?"),0),B8) -> 1968 | K8: =IF(C8="?","Sep",C8) -> Oct | L8: =IF(Table1[[#This Row],[Hospital tier]]="?","tier - 2",Table1[[#This Row],[Hospital tier]]) -> tier - 1 | M8: =IF(Table1[[#This Row],[City tier]]="?","tier - 2",Table1[[#This Row],[City tier]]) -> tier - 3 | N8: =IF(Table1[[#This Row],[State ID]]="?","Unknown",Table1[[#This Row],[State ID]]) -> R1013 | O8: =IF(Table1[[#This Row],[Customer ID]]="?","Unknown",Table1[[#This Row],[Customer ID]]) -> Id1
A9: Id10 | B9: 1978 | C9: Dec | D9: 29 | E9: 0 | F9: 48885.14 | G9: tier - 1 | H9: tier - 2 | I9: R1013 | J9: =IF(B9="?",ROUND(AVERAGEIF($B$2:$B$2344,"<>?"),0),B9) -> 1978 | K9: =IF(C9="?","Sep",C9) -> Dec | L9: =IF(Table1[[#This Row],[Hospital tier]]="?","tier - 2",Table1[[#This Row],[Hospital tier]]) -> tier - 1 | M9: =IF(Table1[[#This Row],[City tier]]="?","tier - 2",Table1[[#This Row],[City tier]]) -> tier - 2 | N9: =IF(Table1[[#This Row],[State ID]]="?","Unknown",Table1[[#This Row],[State ID]]) -> R1013 | O9: =IF(Table1[[#This Row],[Customer ID]]="?","Unknown",Table1[[#This Row],[Customer ID]]) -> Id10
A10: Id100 | B10: 1977 | C10: Jun | D10: 27 | E10: 2 | F10: 40284.38 | G10: tier - 1 | H10: tier - 3 | I10: R1012 | J10: =IF(B10="?",ROUND(AVERAGEIF($B$2:$B$2344,"<>?"),0),B10) -> 1977 | K10: =IF(C10="?","Sep",C10) -> Jun | L10: =IF(Table1[[#This Row],[Hospital tier]]="?","tier - 2",Table1[[#This Row],[Hospital tier]]) -> tier - 1 | M10: =IF(Table1[[#This Row],[City tier]]="?","tier - 2",Table1[[#This Row],[City tier]]) -> tier - 3 | N10: =IF(Table1[[#This Row],[State ID]]="?","Unknown",Table1[[#This Row],[State ID]]) -> R1012 | O10: =IF(Table1[[#This Row],[Customer ID]]="?","Unknown",Table1[[#This Row],[Customer ID]]) -> Id100
A11: Id1000 | B11: 1989 | C11: Dec | D11: 17 | E11: 3 | F11: 11250.43 | G11: tier - 3 | H11: tier - 2 | I11: R1026 | J11: =IF(B11="?",ROUND(AVERAGEIF($B$2:$B$2344,"<>?"),0),B11) -> 1989 | K11: =IF(C11="?","Sep",C11) -> Dec | L11: =IF(Table1[[#This Row],[Hospital tier]]="?","tier - 2",Table1[[#This Row],[Hospital tier]]) -> tier - 3 | M11: =IF(Table1[[#This Row],[City tier]]="?","tier - 2",Table1[[#This Row],[City tier]]) -> tier - 2 | N11: =IF(Table1[[#This Row],[State ID]]="?","Unknown",Table1[[#This Row],[State ID]]) -> R1026 | O11: =IF(Table1[[#This Row],[Customer ID]]="?","Unknown",Table1[[#This Row],[Customer ID]]) -> Id1000
A12: Id1001 | B12: 1969 | C12: Dec | D12: 30 | E12: 2 | F12: 11244.38 | G12: tier - 3 | H12: tier - 1 | I12: R1016 | J12: =IF(B12="?",ROUND(AVERAGEIF($B$2:$B$2344,"<>?"),0),B12) -> 1969 | K12: =IF(C12="?","Sep",C12) -> Dec | L12: =IF(Table1[[#This Row],[Hospital tier]]="?","tier - 2",Table1[[#This Row],[Hospital tier]]) -> tier - 3 | M12: =IF(Table1[[#This Row],[City tier]]="?","tier - 2",Table1[[#This Row],[City tier]]) -> tier - 1 | N12: =IF(Table1[[#This Row],[State ID]]="?","Unknown",Table1[[#This Row],[State ID]]) -> R1016 | O12: =IF(Table1[[#This Row],[Customer ID]]="?","Unknown",Table1[[#This Row],[Customer ID]]) -> Id1001
A13: Id1002 | B13: 1976 | C13: Jun | D13: 28 | E13: 2 | F13: 11217.35 | G13: tier - 3 | H13: tier - 2 | I13: R1025 | J13: =IF(B13="?",ROUND(AVERAGEIF($B$2:$B$2344,"<>?"),0),B13) -> 1976 | K13: =IF(C13="?","Sep",C13) -> Jun | L13: =IF(Table1[[#This Row],[Hospital tier]]="?","tier - 2",Table1[[#This Row],[Hospital tier]]) -> tier - 3 | M13: =IF(Table1[[#This Row],[City tier]]="?","tier - 2",Table1[[#This Row],[City tier]]) -> tier - 2 | N13: =IF(Table1[[#This Row],[State ID]]="?","Unknown",Table1[[#This Row],[State ID]]) -> R1025 | O13: =IF(Table1[[#This Row],[Customer ID]]="?","Unknown",Table1[[#This Row],[Customer ID]]) -> Id1002
... A326: Id1285 | B326: 1975 | C326: Aug | D326: 6 | E326: 1 | F326: 8551.35 | G326: tier - 2 | H326: tier - 2 | I326: R1011 | J326: =IF(B326="?",ROUND(AVERAGEIF($B$2:$B$2344,"<>?"),0),B326) -> 1975 | K326: =IF(C326="?","Sep",C326) -> Aug | L326: =IF(Table1[[#This Row],[Hospital tier]]="?","tier - 2",Table1[[#This Row],[Hospital tier]]) -> tier - 2 | M326: =IF(Table1[[#This Row],[City tier]]="?","tier - 2",Table1[[#This Row],[City tier]]) -> tier - 2 | N326: =IF(Table1[[#This Row],[State ID]]="?","Unknown",Table1[[#This Row],[State ID]]) -> R1011 | O326: =IF(Table1[[#This Row],[Customer ID]]="?","Unknown",Table1[[#This Row],[Customer ID]]) -> Id1285
A327: Id1286 | B327: ? | C327: Dec | D327: 12 | E327: 1 | F327: 8547.69 | G327: tier - 2 | H327: tier - 1 | I327: R1013 | J327: =IF(B327="?",ROUND(AVERAGEIF($B$2:$B$2344,"<>?"),0),B327) -> 1983 | K327: =IF(C327="?","Sep",C327) -> Dec | L327: =IF(Table1[[#This Row],[Hospital tier]]="?","tier - 2",Table1[[#This Row],[Hospital tier]]) -> tier - 2 | M327: =IF(Table1[[#This Row],[City tier]]="?","tier - 2",Table1[[#This Row],[City tier]]) -> tier - 1 | N327: =IF(Table1[[#This Row],[State ID]]="?","Unknown",Table1[[#This Row],[State ID]]) -> R1013 | O327: =IF(Table1[[#This Row],[Customer ID]]="?","Unknown",Table1[[#This Row],[Customer ID]]) -> Id1286
A328: Id1287 | B328: 1975 | C328: Nov | D328: 6 | E328: 1 | F328: 8539.67 | G328: tier - 2 | H328: tier - 3 | I328: R1011 | J328: =IF(B328="?",ROUND(AVERAGEIF($B$2:$B$2344,"<>?"),0),B328) -> 1975 | K328: =IF(C328="?","Sep",C328) -> Nov | L328: =IF(Table1[[#This Row],[Hospital tier]]="?","tier - 2",Table1[[#This Row],[Hospital tier]]) -> tier - 2 | M328: =IF(Table1[[#This Row],[City tier]]="?","tier - 2",Table1[[#This Row],[City tier]]) -> tier - 3 | N328: =IF(Table1[[#This Row],[State ID]]="?","Unknown",Table1[[#This Row],[State ID]]) -> R1011 | O328: =IF(Table1[[#This Row],[Customer ID]]="?","Unknown",Table1[[#This Row],[Customer ID]]) -> Id1287
A329: Id1288 | B329: 1981 | C329: Dec | D329: 27 | E329: 3 | F329: 8538.29 | G329: tier - 2 | H329: tier - 3 | I329: R1024 | J329: =IF(B329="?",ROUND(AVERAGEIF($B$2:$B$2344,"<>?"),0),B329) -> 1981 | K329: =IF(C329="?","Sep",C329) -> Dec | L329: =IF(Table1[[#This Row],[Hospital tier]]="?","tier - 2",Table1[[#This Row],[Hospital tier]]) -> tier - 2 | M329: =IF(Table1[[#This Row],[City tier]]="?","tier - 2",Table1[[#This Row],[City tier]]) -> tier - 3 | N329: =IF(Table1[[#This Row],[State ID]]="?","Unknown",Table1[[#This Row],[State ID]]) -> R1024 | O329: =IF(Table1[[#This Row],[Customer ID]]="?","Unknown",Table1[[#This Row],[Customer ID]]) -> Id1288
A330: Id1289 | B330: ? | C330: Jul | D330: 24 | E330: 0 | F330: 8534.67 | G330: tier - 2 | H330: tier - 3 | I330: R1024 | J330: =IF(B330="?",ROUND(AVERAGEIF($B$2:$B$2344,"<>?"),0),B330) -> 1983 | K330: =IF(C330="?","Sep",C330) -> Jul | L330: =IF(Table1[[#This Row],[Hospital tier]]="?","tier - 2",Table1[[#This Row],[Hospital tier]]) -> tier - 2 | M330: =IF(Table1[[#This Row],[City tier]]="?","tier - 2",Table1[[#This Row],[City tier]]) -> tier - 3 | N330: =IF(Table1[[#This Row],[State ID]]="?","Unknown",Table1[[#This Row],[State ID]]) -> R1024 | O330: =IF(Table1[[#This Row],[Customer ID]]="?","Unknown",Table1[[#This Row],[Customer ID]]) -> Id1289
A331: Id129 | B331: 1985 | C331: Sep | D331: 20 | E331: 1 | F331: 39047.29 | G331: tier - 1 | H331: tier - 3 | I331: R1017 | J331: =IF(B331="?",ROUND(AVERAGEIF($B$2:$B$2344,"<>?"),0),B331) -> 1985 | K331: =IF(C331="?","Sep",C331) -> Sep | L331: =IF(Table1[[#This Row],[Hospital tier]]="?","tier - 2",Table1[[#This Row],[Hospital tier]]) -> tier - 1 | M331: =IF(Table1[[#This Row],[City tier]]="?","tier - 2",Table1[[#This Row],[City tier]]) -> tier - 3 | N331: =IF(Table1[[#This Row],[State ID]]="?","Unknown",Table1[[#This Row],[State ID]]) -> R1017 | O331: =IF(Table1[[#This Row],[Customer ID]]="?","Unknown",Table1[[#This Row],[Customer ID]]) -> Id129
A332: Id1290 | B332: 1977 | C332: Jul | D332: 26 | E332: 2 | F332: 8527.53 | G332: tier - 2 | H332: tier - 2 | I332: R1013 | J332: =IF(B332="?",ROUND(AVERAGEIF($B$2:$B$2344,"<>?"),0),B332) -> 1977 | K332: =IF(C332="?","Sep",C332) -> Jul | L332: =IF(Table1[[#This Row],[Hospital tier]]="?","tier - 2",Table1[[#This Row],[Hospital tier]]) -> tier - 2 | M332: =IF(Table1[[#This Row],[City tier]]="?","tier - 2",Table1[[#This Row],[City tier]]) -> tier - 2 | N332: =IF(Table1[[#This Row],[State ID]]="?","Unknown",Table1[[#This Row],[State ID]]) -> R1013 | O332: =IF(Table1[[#This Row],[Customer ID]]="?","Unknown",Table1[[#This Row],[Customer ID]]) -> Id1290
A333: Id1291 | B333: 1979 | C333: Aug | D333: 13 | E333: 3 | F333: 8522 | G333: tier - 2 | H333: tier - 2 | I333: R1011 | J333: =IF(B333="?",ROUND(AVERAGEIF($B$2:$B$2344,"<>?"),0),B333) -> 1979 | K333: =IF(C333="?","Sep",C333) -> Aug | L333: =IF(Table1[[#This Row],[Hospital tier]]="?","tier - 2",Table1[[#This Row],[Hospital tier]]) -> tier - 2 | M333: =IF(Table1[[#This Row],[City tier]]="?","tier - 2",Table1[[#This Row],[City tier]]) -> tier - 2 | N333: =IF(Table1[[#This Row],[State ID]]="?","Unknown",Table1[[#This Row],[State ID]]) -> R1011 | O333: =IF(Table1[[#This Row],[Customer ID]]="?","Unknown",Table1[[#This Row],[Customer ID]]) -> Id1291
A334: Id1292 | B334: 1977 | C334: Dec | D334: 29 | E334: 2 | F334: 8520.03 | G334: tier - 2 | H334: tier - 3 | I334: R1011 | J334: =IF(B334="?",ROUND(AVERAGEIF($B$2:$B$2344,"<>?"),0),B334) -> 1977 | K334: =IF(C334="?","Sep",C334) -> Dec | L334: =IF(Table1[[#This Row],[Hospital tier]]="?","tier - 2",Table1[[#This Row],[Hospital tier]]) -> tier - 2 | M334: =IF(Table1[[#This Row],[City tier]]="?","tier - 2",Table1[[#This Row],[City tier]]) -> tier - 3 | N334: =IF(Table1[[#This Row],[State ID]]="?","Unknown",Table1[[#This Row],[State ID]]) -> R1011 | O334: =IF(Table1[[#This Row],[Customer ID]]="?","Unknown",Table1[[#This Row],[Customer ID]]) -> Id1292
A335: Id1293 | B335: 1977 | C335: Jun | D335: 21 | E335: 2 | F335: 8516.83 | G335: tier - 2 | H335: tier - 1 | I335: R1013 | J335: =IF(B335="?",ROUND(AVERAGEIF($B$2:$B$2344,"<>?"),0),B335) -> 1977 | K335: =IF(C335="?","Sep",C335) -> Jun | L335: =IF(Table1[[#This Row],[Hospital tier]]="?","tier - 2",Table1[[#This Row],[Hospital tier]]) -> tier - 2 | M335: =IF(Table1[[#This Row],[City tier]]="?","tier - 2",Table1[[#This Row],[City tier]]) -> tier - 1 | N335: =IF(Table1[[#This Row],[State ID]]="?","Unknown",Table1[[#This Row],[State ID]]) -> R1013 | O335: =IF(Table1[[#This Row],[Customer ID]]="?","Unknown",Table1[[#This Row],[Customer ID]]) -> Id1293
A336: Id1294 | B336: 1977 | C336: Dec | D336: 26 | E336: 2 | F336: 8515.76 | G336: tier - 2 | H336: tier - 2 | I336: R1013 | J336: =IF(B336="?",ROUND(AVERAGEIF($B$2:$B$2344,"<>?"),0),B336) -> 1977 | K336: =IF(C336="?","Sep",C336) -> Dec | L336: =IF(Table1[[#This Row],[Hospital tier]]="?","tier - 2",Table1[[#This Row],[Hospital tier]]) -> tier - 2 | M336: =IF(Table1[[#This Row],[City tier]]="?","tier - 2",Table1[[#This Row],[City tier]]) -> tier - 2 | N336: =IF(Table1[[#This Row],[State ID]]="?","Unknown",Table1[[#This Row],[State ID]]) -> R1013 | O336: =IF(Table1[[#This Row],[Customer ID]]="?","Unknown",Table1[[#This Row],[Customer ID]]) -> Id1294
A337: Id1295 | B337: 1993 | C337: Nov | D337: 10 | E337: 0 | F337: 8471.65 | G337: tier - 2 | H337: tier - 1 | I337: R1012 | J337: =IF(B337="?",ROUND(AVERAGEIF($B$2:$B$2344,"<>?"),0),B337) -> 1993 | K337: =IF(C337="?","Sep",C337) -> Nov | L337: =IF(Table1[[#This Row],[Hospital tier]]="?","tier - 2",Table1[[#This Row],[Hospital tier]]) -> tier - 2 | M337: =IF(Table1[[#This Row],[City tier]]="?","tier - 2",Table1[[#This Row],[City tier]]) -> tier - 1 | N337: =IF(Table1[[#This Row],[State ID]]="?","Unknown",Table1[[#This Row],[State ID]]) -> R1012 | O337: =IF(Table1[[#This Row],[Customer ID]]="?","Unknown",Table1[[#This Row],[Customer ID]]) -> Id1295
A338: Id1296 | B338: 1992 | C338: Sep | D338: 9 | E338: 0 | F338: 8466.35 | G338: tier - 2 | H338: tier - 2 | I338: R1012 | J338: =IF(B338="?",ROUND(AVERAGEIF($B$2:$B$2344,"<>?"),0),B338) -> 1992 | K338: =IF(C338="?","Sep",C338) -> Sep | L338: =IF(Table1[[#This Row],[Hospital tier]]="?","tier - 2",Table1[[#This Row],[Hospital tier]]) -> tier - 2 | M338: =IF(Table1[[#This Row],[City tier]]="?","tier - 2",Table1[[#This Row],[City tier]]) -> tier - 2 | N338: =IF(Table1[[#This Row],[State ID]]="?","Unknown",Table1[[#This Row],[State ID]]) -> R1012 | O338: =IF(Table1[[#This Row],[Customer ID]]="?","Unknown",Table1[[#This Row],[Customer ID]]) -> Id1296
A339: Id1297 | B339: 1972 | C339: Dec | D339: 26 | E339: 0 | F339: 8457.82 | G339: tier - 2 | H339: tier - 3 | I339: R1011 | J339: =IF(B339="?",ROUND(AVERAGEIF($B$2:$B$2344,"<>?"),0),B339) -> 1972 | K339: =IF(C339="?","Sep",C339) -> Dec | L339: =IF(Table1[[#This Row],[Hospital tier]]="?","tier - 2",Table1[[#This Row],[Hospital tier]]) -> tier - 2 | M339: =IF(Table1[[#This Row],[City tier]]="?","tier - 2",Table1[[#This Row],[City tier]]) -> tier - 3 | N339: =IF(Table1[[#This Row],[State ID]]="?","Unknown",Table1[[#This Row],[State ID]]) -> R1011 | O339: =IF(Table1[[#This Row],[Customer ID]]="?","Unknown",Table1[[#This Row],[Customer ID]]) -> Id1297
A340: Id1298 | B340: 1984 | C340: Jun | D340: 19 | E340: 3 | F340: 8450.82 | G340: tier - 2 | H340: tier - 2 | I340: R1025 | J340: =IF(B340="?",ROUND(AVERAGEIF($B$2:$B$2344,"<>?"),0),B340) -> 1984 | K340: =IF(C340="?","Sep",C340) -> Jun | L340: =IF(Table1[[#This Row],[Hospital tier]]="?","tier - 2",Table1[[#This Row],[Hospital tier]]) -> tier - 2 | M340: =IF(Table1[[#This Row],[City tier]]="?","tier - 2",Table1[[#This Row],[City tier]]) -> tier - 2 | N340: =IF(Table1[[#This Row],[State ID]]="?","Unknown",Table1[[#This Row],[State ID]]) -> R1025 | O340: =IF(Table1[[#This Row],[Customer ID]]="?","Unknown",Table1[[#This Row],[Customer ID]]) -> Id1298
A341: Id1299 | B341: 1966 | C341: Jun | D341: 12 | E341: 0 | F341: 8448.66 | G341: tier - 3 | H341: tier - 1 | I341: R1013 | J341: =IF(B341="?",ROUND(AVERAGEIF($B$2:$B$2344,"<>?"),0),B341) -> 1966 | K341: =IF(C341="?","Sep",C341) -> Jun | L341: =IF(Table1[[#This Row],[Hospital tier]]="?","tier - 2",Table1[[#This Row],[Hospital tier]]) -> tier - 3 | M341: =IF(Table1[[#This Row],[City tier]]="?","tier - 2",Table1[[#This Row],[City tier]]) -> tier - 1 | N341: =IF(Table1[[#This Row],[State ID]]="?","Unknown",Table1[[#This Row],[State ID]]) -> R1013 | O341: =IF(Table1[[#This Row],[Customer ID]]="?","Unknown",Table1[[#This Row],[Customer ID]]) -> Id1299
A342: Id13 | B342: 1962 | C342: Oct | D342: 11 | E342: 0 | F342: 48673.56 | G342: tier - 1 | H342: tier - 2 | I342: R1013 | J342: =IF(B342="?",ROUND(AVERAGEIF($B$2:$B$2344,"<>?"),0),B342) -> 1962 | K342: =IF(C342="?","Sep",C342) -> Oct | L342: =IF(Table1[[#This Row],[Hospital tier]]="?","tier - 2",Table1[[#This Row],[Hospital tier]]) -> tier - 1 | M342: =IF(Table1[[#This Row],[City tier]]="?","tier - 2",Table1[[#This Row],[City tier]]) -> tier - 2 | N342: =IF(Table1[[#This Row],[State ID]]="?","Unknown",Table1[[#This Row],[State ID]]) -> R1013 | O342: =IF(Table1[[#This Row],[Customer ID]]="?","Unknown",Table1[[#This Row],[Customer ID]]) -> Id13
... A2344: Id999 | B2344: 1969 | C2344: Aug | D2344: 20 | E2344: 3 | F2344: 11253.42 | G2344: tier - 3 | H2344: tier - 1 | I2344: R1011 | J2344: =IF(B2344="?",ROUND(AVERAGEIF($B$2:$B$2344,"<>?"),0),B2344) -> 1969 | K2344: =IF(C2344="?","Sep",C2344) -> Aug | L2344: =IF(Table1[[#This Row],[Hospital tier]]="?","tier - 2",Table1[[#This Row],[Hospital tier]]) -> tier - 3 | M2344: =IF(Table1[[#This Row],[City tier]]="?","tier - 2",Table1[[#This Row],[City tier]]) -> tier - 1 | N2344: =IF(Table1[[#This Row],[State ID]]="?","Unknown",Table1[[#This Row],[State ID]]) -> R1011 | O2344: =IF(Table1[[#This Row],[Customer ID]]="?","Unknown",Table1[[#This Row],[Customer ID]]) -> Id999

Sheet Medical Examinations
A1: Customer ID | B1: BMI | C1: HBA1C | D1: Heart Issues | E1: Any Transplants | F1: Cancer history | G1: NumberOfMajorSurgeries | H1: smoker
A2: Id1 | B2: 47.41 | C2: 7.47 | D2: No | E2: No | F2: No | G2: No major surgery | H2: yes
A3: Id10 | B3: 38.06 | C3: 10.79 | D3: No | E3: No | F3: No | G3: No major surgery | H3: yes
A4: Id100 | B4: 48.2 | C4: 4.84 | D4: No | E4: No | F4: No | G4: No major surgery | H4: yes
A5: Id1000 | B5: 39.17 | C5: 4.15 | D5: No | E5: No | F5: No | G5: No major surgery | H5: No
A6: Id1001 | B6: 26.41 | C6: 5.99 | D6: yes | E6: No | F6: Yes | G6: 1 | H6: No
A7: Id1002 | B7: 30.63 | C7: 5.8 | D7: yes | E7: No | F7: No | G7: No major surgery | H7: No
A8: Id1003 | B8: 31.73 | C8: 7.32 | D8: yes | E8: No | F8: No | G8: 2 | H8: No
A9: Id1004 | B9: 30.7 | C9: 5.16 | D9: No | E9: No | F9: No | G9: 2 | H9: No
A10: Id1005 | B10: 25.935 | C10: 5.96 | D10: yes | E10: No | F10: No | G10: 2 | H10: No
A11: Id1006 | B11: 35.9 | C11: 4.85 | D11: yes | E11: No | F11: Yes | G11: 1 | H11: No
A12: Id1007 | B12: 26.7 | C12: 5.09 | D12: yes | E12: No | F12: Yes | G12: 1 | H12: No
A13: Id1008 | B13: 33.71 | C13: 4.94 | D13: No | E13: No | F13: No | G13: No major surgery | H13: No
A14: Id1009 | B14: 41.91 | C14: 4.92 | D14: yes | E14: No | F14: No | G14: 2 | H14: No
A15: Id101 | B15: 35.75 | C15: 8 | D15: yes | E15: No | F15: No | G15: No major surgery | H15: yes
A16: Id1010 | B16: 39.82 | C16: 6.05 | D16: yes | E16: No | F16: No | G16: 2 | H16: No
A17: Id1011 | B17: 28.12 | C17: 4.67 | D17: No | E17: No | F17: No | G17: 2 | H17: No
A18: Id1012 | B18: 26.98 | C18: 9.81 | D18: yes | E18: No | F18: No | G18: No major surgery | H18: No
A19: Id1013 | B19: 27.2 | C19: 6.06 | D19: yes | E19: No | F19: No | G19: 2 | H19: No
A20: Id1014 | B20: 25.3 | C20: 5.19 | D20: yes | E20: No | F20: No | G20: 2 | H20: No
A21: Id1015 | B21: 30.25 | C21: 10.16 | D21: No | E21: No | F21: No | G21: No major surgery | H21: No
A22: Id1016 | B22: 54 | C22: 4.68 | D22: yes | E22: yes | F22: No | G22: 2 | H22: No
A23: Id1017 | B23: 51.86 | C23: 5.32 | D23: yes | E23: No | F23: No | G23: No major surgery | H23: No
A24: Id1018 | B24: 31.39 | C24: 6.99 | D24: No | E24: No | F24: No | G24: No major surgery | H24: No
A25: Id1019 | B25: 39.97 | C25: 5.55 | D25: No | E25: No | F25: No | G25: No major surgery | H25: No
A26: Id102 | B26: 53.81 | C26: 8.77 | D26: yes | E26: No | F26: No | G26: No major surgery | H26: yes
A27: Id1020 | B27: 41.23 | C27: 6.94 | D27: No | E27: No | F27: No | G27: No major surgery | H27: No
A28: Id1021 | B28: 49.45 | C28: 4.2 | D28: yes | E28: No | F28: No | G28: No major surgery | H28: No
A29: Id1022 | B29: 41.04 | C29: 5.59 | D29: No | E29: No | F29: No | G29: No major surgery | H29: No
A30: Id1023 | B30: 27.93 | C30: 9.96 | D30: No | E30: No | F30: No | G30: No major surgery | H30: No
A31: Id1024 | B31: 21.01 | C31: 7.37 | D31: No | E31: No | F31: No | G31: No major surgery | H31: No
A32: Id1025 | B32: 52.37 | C32: 5.06 | D32: yes | E32: yes | F32: No | G32: 2 | H32: No
A33: Id1026 | B33: 40.37 | C33: 8.21 | D33: No | E33: No | F33: No | G33: No major surgery | H33: No
A34: Id1027 | B34: 41.47 | C34: 10.34 | D34: No | E34: No | F34: No | G34: 2 | H34: No
A35: Id1028 | B35: 33.725 | C35: 5.51 | D35: yes | E35: No | F35: No | G35: 2 | H35: No
A36: Id1029 | B36: 28.1 | C36: 11.2 | D36: No | E36: No | F36: No | G36: No major surgery | H36: No
A37: Id103 | B37: 49.48 | C37: 4.96 | D37: No | E37: No | F37: Yes | G37: 1 | H37: yes
A38: Id1030 | B38: 37.43 | C38: 4.35 | D38: yes | E38: No | F38: Yes | G38: 1 | H38: No
A39: Id1031 | B39: 23.7 | C39: 10.45 | D39: No | E39: No | F39: No | G39: No major surgery | H39: No
A40: Id1032 | B40: 24.795 | C40: 4.07 | D40: yes | E40: No | F40: Yes | G40: 1 | H40: No
...

Sheet Customer Names
A1: Customer ID | B1: name | C1: Title | D1: First Name | E1: Last Name
A2: Id1 | B2: Hawks, Ms. Kelly | C2: Ms | D2: Kelly | E2: Hawks | F2: =TRIM(D2) -> Kelly | G2: =TRIM(C2) -> Ms
A3: Id10 | B3: Benner, Ms. Brooke N. | C3: Ms | D3: Brooke N | E3: Benner | F3: =TRIM(D3) -> Brooke N | G3: =TRIM(C3) -> Ms
A4: Id100 | B4: Gollins, Mr. Daniel | C4: Mr | D4: Daniel | E4: Gollins | F4: =TRIM(D4) -> Daniel | G4: =TRIM(C4) -> Mr
A5: Id1000 | B5: Schaefer, Mrs. Stephanie A | C5: Mrs | D5: Stephanie A | E5: Schaefer | F5: =TRIM(D5) -> Stephanie A | G5: =TRIM(C5) -> Mrs
A6: Id1001 | B6: D'Alessandro, Mr. Patrick | C6: Mr | D6: Patrick | E6: D'Alessandro | F6: =TRIM(D6) -> Patrick | G6: =TRIM(C6) -> Mr
A7: Id1002 | B7: Wyss, Mrs. Krista | C7: Mrs | D7: Krista | E7: Wyss | F7: =TRIM(D7) -> Krista | G7: =TRIM(C7) -> Mrs
A8: Id1003 | B8: Rose, Ms. Jenessa | C8: Ms | D8: Jenessa | E8: Rose | F8: =TRIM(D8) -> Jenessa | G8: =TRIM(C8) -> Ms
A9: Id1004 | B9: Hopper, Mr. Ryan M. | C9: Mr | D9: Ryan M | E9: Hopper | F9: =TRIM(D9) -> Ryan M | G9: =TRIM(C9) -> Mr
A10: Id1005 | B10: Finneran, Mr. Thomas | C10: Mr | D10: Thomas | E10: Finneran | F10: =TRIM(D10) -> Thomas | G10: =TRIM(C10) -> Mr
A11: Id1006 | B11: Basham, Ms. Amanda N. | C11: Ms | D11: Amanda N | E11: Basham | F11: =TRIM(D11) -> Amanda N | G11: =TRIM(C11) -> Ms
A12: Id1007 | B12: Inman, Ms. Teresa P. | C12: Ms | D12: Teresa P | E12: Inman | F12: =TRIM(D12) -> Teresa P | G12: =TRIM(C12) -> Ms
A13: Id1008 | B13: Oscal, Mr. Dorian | C13: Mr | D13: Dorian | E13: Oscal | F13: =TRIM(D13) -> Dorian | G13: =TRIM(C13) -> Mr
... A2336: Id999 | B2336: Campbell, Mr. Jonathon M. | C2336: Mr | D2336: Jonathon M | E2336: Campbell | F2336: =TRIM(D2336) -> Jonathon M | G2336: =TRIM(C2336) -> Mr

Sheet Cleaned Medical Examiation data
A1: Customer ID | B1: BMI | C1: HBA1C | D1: Heart Issues | E1: Any Transplants | F1: Cancer history | G1: Number Of Major Surgeries | H1: Smoker | I1: Number Of Major Surgeries | J1: Weight Status | K1: Diabetes Status
A2: Id1 | B2: 47.41 | C2: 7.47 | D2: NO | E2: NO | F2: NO | G2: No major surgery | H2: YES | I2: =IF(G2="No major surgery",0,G2) -> 0 | J2: {=_xlfn.IFS(B2<18.5,"Under Weight",B2<=24.9,"Normal Weight",B2<=29.999,"Over Weight",B2>=30,"Obesity")} -> Obesity | K2: {=_xlfn.IFS(C2<5.7,"Normal",C2<=6.4,"Prediabetes",C2>6.4,"Diabetes")} -> Diabetes
A3: Id10 | B3: 38.06 | C3: 10.79 | D3: NO | E3: NO | F3: NO | G3: No major surgery | H3: YES | I3: =IF(G3="No major surgery",0,G3) -> 0 | J3: {=_xlfn.IFS(B3<18.5,"Under Weight",B3<=24.9,"Normal Weight",B3<=29.999,"Over Weight",B3>=30,"Obesity")} -> Obesity | K3: {=_xlfn.IFS(C3<5.7,"Normal",C3<=6.4,"Prediabetes",C3>6.4,"Diabetes")} -> Diabetes
A4: Id100 | B4: 48.2 | C4: 4.84 | D4: NO | E4: NO | F4: NO | G4: No major surgery | H4: YES | I4: =IF(G4="No major surgery",0,G4) -> 0 | J4: {=_xlfn.IFS(B4<18.5,"Under Weight",B4<=24.9,"Normal Weight",B4<=29.999,"Over Weight",B4>=30,"Obesity")} -> Obesity | K4: {=_xlfn.IFS(C4<5.7,"Normal",C4<=6.4,"Prediabetes",C4>6.4,"Diabetes")} -> Normal
A5: Id1000 | B5: 39.17 | C5: 4.15 | D5: NO | E5: NO | F5: NO | G5: No major surgery | H5: NO | I5: =IF(G5="No major surgery",0,G5) -> 0 | J5: {=_xlfn.IFS(B5<18.5,"Under Weight",B5<=24.9,"Normal Weight",B5<=29.999,"Over Weight",B5>=30,"Obesity")} -> Obesity | K5: {=_xlfn.IFS(C5<5.7,"Normal",C5<=6.4,"Prediabetes",C5>6.4,"Diabetes")} -> Normal
A6: Id1001 | B6: 26.41 | C6: 5.99 | D6: YES | E6: NO | F6: YES | G6: 1 | H6: NO | I6: =IF(G6="No major surgery",0,G6) -> 1 | J6: {=_xlfn.IFS(B6<18.5,"Under Weight",B6<=24.9,"Normal Weight",B6<=29.999,"Over Weight",B6>=30,"Obesity")} -> Over Weight | K6: {=_xlfn.IFS(C6<5.7,"Normal",C6<=6.4,"Prediabetes",C6>6.4,"Diabetes")} -> Prediabetes
A7: Id1002 | B7: 30.63 | C7: 5.8 | D7: YES | E7: NO | F7: NO | G7: No major surgery | H7: NO | I7: =IF(G7="No major surgery",0,G7) -> 0 | J7: {=_xlfn.IFS(B7<18.5,"Under Weight",B7<=24.9,"Normal Weight",B7<=29.999,"Over Weight",B7>=30,"Obesity")} -> Obesity | K7: {=_xlfn.IFS(C7<5.7,"Normal",C7<=6.4,"Prediabetes",C7>6.4,"Diabetes")} -> Prediabetes
A8: Id1003 | B8: 31.73 | C8: 7.32 | D8: YES | E8: NO | F8: NO | G8: 2 | H8: NO | I8: =IF(G8="No major surgery",0,G8) -> 2 | J8: {=_xlfn.IFS(B8<18.5,"Under Weight",B8<=24.9,"Normal Weight",B8<=29.999,"Over Weight",B8>=30,"Obesity")} -> Obesity | K8: {=_xlfn.IFS(C8<5.7,"Normal",C8<=6.4,"Prediabetes",C8>6.4,"Diabetes")} -> Diabetes
A9: Id1004 | B9: 30.7 | C9: 5.16 | D9: NO | E9: NO | F9: NO | G9: 2 | H9: NO | I9: =IF(G9="No major surgery",0,G9) -> 2 | J9: {=_xlfn.IFS(B9<18.5,"Under Weight",B9<=24.9,"Normal Weight",B9<=29.999,"Over Weight",B9>=30,"Obesity")} -> Obesity | K9: {=_xlfn.IFS(C9<5.7,"Normal",C9<=6.4,"Prediabetes",C9>6.4,"Diabetes")} -> Normal
A10: Id1005 | B10: 25.935 | C10: 5.96 | D10: YES | E10: NO | F10: NO | G10: 2 | H10: NO | I10: =IF(G10="No major surgery",0,G10) -> 2 | J10: {=_xlfn.IFS(B10<18.5,"Under Weight",B10<=24.9,"Normal Weight",B10<=29.999,"Over Weight",B10>=30,"Obesity")} -> Over Weight | K10: {=_xlfn.IFS(C10<5.7,"Normal",C10<=6.4,"Prediabetes",C10>6.4,"Diabetes")} -> Prediabetes
A11: Id1006 | B11: 35.9 | C11: 4.85 | D11: YES | E11: NO | F11: YES | G11: 1 | H11: NO | I11: =IF(G11="No major surgery",0,G11) -> 1 | J11: {=_xlfn.IFS(B11<18.5,"Under Weight",B11<=24.9,"Normal Weight",B11<=29.999,"Over Weight",B11>=30,"Obesity")} -> Obesity | K11: {=_xlfn.IFS(C11<5.7,"Normal",C11<=6.4,"Prediabetes",C11>6.4,"Diabetes")} -> Normal
A12: Id1007 | B12: 26.7 | C12: 5.09 | D12: YES | E12: NO | F12: YES | G12: 1 | H12: NO | I12: =IF(G12="No major surgery",0,G12) -> 1 | J12: {=_xlfn.IFS(B12<18.5,"Under Weight",B12<=24.9,"Normal Weight",B12<=29.999,"Over Weight",B12>=30,"Obesity")} -> Over Weight | K12: {=_xlfn.IFS(C12<5.7,"Normal",C12<=6.4,"Prediabetes",C12>6.4,"Diabetes")} -> Normal
A13: Id1008 | B13: 33.71 | C13: 4.94 | D13: NO | E13: NO | F13: NO | G13: No major surgery | H13: NO | I13: =IF(G13="No major surgery",0,G13) -> 0 | J13: {=_xlfn.IFS(B13<18.5,"Under Weight",B13<=24.9,"Normal Weight",B13<=29.999,"Over Weight",B13>=30,"Obesity")} -> Obesity | K13: {=_xlfn.IFS(C13<5.7,"Normal",C13<=6.4,"Prediabetes",C13>6.4,"Diabetes")} -> Normal
A14: Id1009 | B14: 41.91 | C14: 4.92 | D14: YES | E14: NO | F14: NO | G14: 2 | H14: NO | I14: =IF(G14="No major surgery",0,G14) -> 2 | J14: {=_xlfn.IFS(B14<18.5,"Under Weight",B14<=24.9,"Normal Weight",B14<=29.999,"Over Weight",B14>=30,"Obesity")} -> Obesity | K14: {=_xlfn.IFS(C14<5.7,"Normal",C14<=6.4,"Prediabetes",C14>6.4,"Diabetes")} -> Normal
A15: Id101 | B15: 35.75 | C15: 8 | D15: YES | E15: NO | F15: NO | G15: No major surgery | H15: YES | I15: =IF(G15="No major surgery",0,G15) -> 0 | J15: {=_xlfn.IFS(B15<18.5,"Under Weight",B15<=24.9,"Normal Weight",B15<=29.999,"Over Weight",B15>=30,"Obesity")} -> Obesity | K15: {=_xlfn.IFS(C15<5.7,"Normal",C15<=6.4,"Prediabetes",C15>6.4,"Diabetes")} -> Diabetes
A16: Id1010 | B16: 39.82 | C16: 6.05 | D16: YES | E16: NO | F16: NO | G16: 2 | H16: NO | I16: =IF(G16="No major surgery",0,G16) -> 2 | J16: {=_xlfn.IFS(B16<18.5,"Under Weight",B16<=24.9,"Normal Weight",B16<=29.999,"Over Weight",B16>=30,"Obesity")} -> Obesity | K16: {=_xlfn.IFS(C16<5.7,"Normal",C16<=6.4,"Prediabetes",C16>6.4,"Diabetes")} -> Prediabetes
A17: Id1011 | B17: 28.12 | C17: 4.67 | D17: NO | E17: NO | F17: NO | G17: 2 | H17: NO | I17: =IF(G17="No major surgery",0,G17) -> 2 | J17: {=_xlfn.IFS(B17<18.5,"Under Weight",B17<=24.9,"Normal Weight",B17<=29.999,"Over Weight",B17>=30,"Obesity")} -> Over Weight | K17: {=_xlfn.IFS(C17<5.7,"Normal",C17<=6.4,"Prediabetes",C17>6.4,"Diabetes")} -> Normal
A18: Id1012 | B18: 26.98 | C18: 9.81 | D18: YES | E18: NO | F18: NO | G18: No major surgery | H18: NO | I18: =IF(G18="No major surgery",0,G18) -> 0 | J18: {=_xlfn.IFS(B18<18.5,"Under Weight",B18<=24.9,"Normal Weight",B18<=29.999,"Over Weight",B18>=30,"Obesity")} -> Over Weight | K18: {=_xlfn.IFS(C18<5.7,"Normal",C18<=6.4,"Prediabetes",C18>6.4,"Diabetes")} -> Diabetes
A19: Id1013 | B19: 27.2 | C19: 6.06 | D19: YES | E19: NO | F19: NO | G19: 2 | H19: NO | I19: =IF(G19="No major surgery",0,G19) -> 2 | J19: {=_xlfn.IFS(B19<18.5,"Under Weight",B19<=24.9,"Normal Weight",B19<=29.999,"Over Weight",B19>=30,"Obesity")} -> Over Weight | K19: {=_xlfn.IFS(C19<5.7,"Normal",C19<=6.4,"Prediabetes",C19>6.4,"Diabetes")} -> Prediabetes
A20: Id1014 | B20: 25.3 | C20: 5.19 | D20: YES | E20: NO | F20: NO | G20: 2 | H20: NO | I20: =IF(G20="No major surgery",0,G20) -> 2 | J20: {=_xlfn.IFS(B20<18.5,"Under Weight",B20<=24.9,"Normal Weight",B20<=29.999,"Over Weight",B20>=30,"Obesity")} -> Over Weight | K20: {=_xlfn.IFS(C20<5.7,"Normal",C20<=6.4,"Prediabetes",C20>6.4,"Diabetes")} -> Normal
A21: Id1015 | B21: 30.25 | C21: 10.16 | D21: NO | E21: NO | F21: NO | G21: No major surgery | H21: NO | I21: =IF(G21="No major surgery",0,G21) -> 0 | J21: {=_xlfn.IFS(B21<18.5,"Under Weight",B21<=24.9,"Normal Weight",B21<=29.999,"Over Weight",B21>=30,"Obesity")} -> Obesity | K21: {=_xlfn.IFS(C21<5.7,"Normal",C21<=6.4,"Prediabetes",C21>6.4,"Diabetes")} -> Diabetes
A22: Id1016 | B22: 54 | C22: 4.68 | D22: YES | E22: YES | F22: NO | G22: 2 | H22: NO | I22: =IF(G22="No major surgery",0,G22) -> 2 | J22: {=_xlfn.IFS(B22<18.5,"Under Weight",B22<=24.9,"Normal Weight",B22<=29.999,"Over Weight",B22>=30,"Obesity")} -> Obesity | K22: {=_xlfn.IFS(C22<5.7,"Normal",C22<=6.4,"Prediabetes",C22>6.4,"Diabetes")} -> Normal
A23: Id1017 | B23: 51.86 | C23: 5.32 | D23: YES | E23: NO | F23: NO | G23: No major surgery | H23: NO | I23: =IF(G23="No major surgery",0,G23) -> 0 | J23: {=_xlfn.IFS(B23<18.5,"Under Weight",B23<=24.9,"Normal Weight",B23<=29.999,"Over Weight",B23>=30,"Obesity")} -> Obesity | K23: {=_xlfn.IFS(C23<5.7,"Normal",C23<=6.4,"Prediabetes",C23>6.4,"Diabetes")} -> Normal
A24: Id1018 | B24: 31.39 | C24: 6.99 | D24: NO | E24: NO | F24: NO | G24: No major surgery | H24: NO | I24: =IF(G24="No major surgery",0,G24) -> 0 | J24: {=_xlfn.IFS(B24<18.5,"Under Weight",B24<=24.9,"Normal Weight",B24<=29.999,"Over Weight",B24>=30,"Obesity")} -> Obesity | K24: {=_xlfn.IFS(C24<5.7,"Normal",C24<=6.4,"Prediabetes",C24>6.4,"Diabetes")} -> Diabetes
A25: Id1019 | B25: 39.97 | C25: 5.55 | D25: NO | E25: NO | F25: NO | G25: No major surgery | H25: NO | I25: =IF(G25="No major surgery",0,G25) -> 0 | J25: {=_xlfn.IFS(B25<18.5,"Under Weight",B25<=24.9,"Normal Weight",B25<=29.999,"Over Weight",B25>=30,"Obesity")} -> Obesity | K25: {=_xlfn.IFS(C25<5.7,"Normal",C25<=6.4,"Prediabetes",C25>6.4,"Diabetes")} -> Normal
A26: Id102 | B26: 53.81 | C26: 8.77 | D26: YES | E26: NO | F26: NO | G26: No major surgery | H26: YES | I26: =IF(G26="No major surgery",0,G26) -> 0 | J26: {=_xlfn.IFS(B26<18.5,"Under Weight",B26<=24.9,"Normal Weight",B26<=29.999,"Over Weight",B26>=30,"Obesity")} -> Obesity | K26: {=_xlfn.IFS(C26<5.7,"Normal",C26<=6.4,"Prediabetes",C26>6.4,"Diabetes")} -> Diabetes
A27: Id1020 | B27: 41.23 | C27: 6.94 | D27: NO | E27: NO | F27: NO | G27: No major surgery | H27: NO | I27: =IF(G27="No major surgery",0,G27) -> 0 | J27: {=_xlfn.IFS(B27<18.5,"Under Weight",B27<=24.9,"Normal Weight",B27<=29.999,"Over Weight",B27>=30,"Obesity")} -> Obesity | K27: {=_xlfn.IFS(C27<5.7,"Normal",C27<=6.4,"Prediabetes",C27>6.4,"Diabetes")} -> Diabetes
A28: Id1021 | B28: 49.45 | C28: 4.2 | D28: YES | E28: NO | F28: NO | G28: No major surgery | H28: NO | I28: =IF(G28="No major surgery",0,G28) -> 0 | J28: {=_xlfn.IFS(B28<18.5,"Under Weight",B28<=24.9,"Normal Weight",B28<=29.999,"Over Weight",B28>=30,"Obesity")} -> Obesity | K28: {=_xlfn.IFS(C28<5.7,"Normal",C28<=6.4,"Prediabetes",C28>6.4,"Diabetes")} -> Normal
A29: Id1022 | B29: 41.04 | C29: 5.59 | D29: NO | E29: NO | F29: NO | G29: No major surgery | H29: NO | I29: =IF(G29="No major surgery",0,G29) -> 0 | J29: {=_xlfn.IFS(B29<18.5,"Under Weight",B29<=24.9,"Normal Weight",B29<=29.999,"Over Weight",B29>=30,"Obesity")} -> Obesity | K29: {=_xlfn.IFS(C29<5.7,"Normal",C29<=6.4,"Prediabetes",C29>6.4,"Diabetes")} -> Normal
A30: Id1023 | B30: 27.93 | C30: 9.96 | D30: NO | E30: NO | F30: NO | G30: No major surgery | H30: NO | I30: =IF(G30="No major surgery",0,G30) -> 0 | J30: {=_xlfn.IFS(B30<18.5,"Under Weight",B30<=24.9,"Normal Weight",B30<=29.999,"Over Weight",B30>=30,"Obesity")} -> Over Weight | K30: {=_xlfn.IFS(C30<5.7,"Normal",C30<=6.4,"Prediabetes",C30>6.4,"Diabetes")} -> Diabetes
A31: Id1024 | B31: 21.01 | C31: 7.37 | D31: NO | E31: NO | F31: NO | G31: No major surgery | H31: NO | I31: =IF(G31="No major surgery",0,G31) -> 0 | J31: {=_xlfn.IFS(B31<18.5,"Under Weight",B31<=24.9,"Normal Weight",B31<=29.999,"Over Weight",B31>=30,"Obesity")} -> Normal Weight | K31: {=_xlfn.IFS(C31<5.7,"Normal",C31<=6.4,"Prediabetes",C31>6.4,"Diabetes")} -> Diabetes
A32: Id1025 | B32: 52.37 | C32: 5.06 | D32: YES | E32: YES | F32: NO | G32: 2 | H32: NO | I32: =IF(G32="No major surgery",0,G32) -> 2 | J32: {=_xlfn.IFS(B32<18.5,"Under Weight",B32<=24.9,"Normal Weight",B32<=29.999,"Over Weight",B32>=30,"Obesity")} -> Obesity | K32: {=_xlfn.IFS(C32<5.7,"Normal",C32<=6.4,"Prediabetes",C32>6.4,"Diabetes")} -> Normal
A33: Id1026 | B33: 40.37 | C33: 8.21 | D33: NO | E33: NO | F33: NO | G33: No major surgery | H33: NO | I33: =IF(G33="No major surgery",0,G33) -> 0 | J33: {=_xlfn.IFS(B33<18.5,"Under Weight",B33<=24.9,"Normal Weight",B33<=29.999,"Over Weight",B33>=30,"Obesity")} -> Obesity | K33: {=_xlfn.IFS(C33<5.7,"Normal",C33<=6.4,"Prediabetes",C33>6.4,"Diabetes")} -> Diabetes
A34: Id1027 | B34: 41.47 | C34: 10.34 | D34: NO | E34: NO | F34: NO | G34: 2 | H34: NO | I34: =IF(G34="No major surgery",0,G34) -> 2 | J34: {=_xlfn.IFS(B34<18.5,"Under Weight",B34<=24.9,"Normal Weight",B34<=29.999,"Over Weight",B34>=30,"Obesity")} -> Obesity | K34: {=_xlfn.IFS(C34<5.7,"Normal",C34<=6.4,"Prediabetes",C34>6.4,"Diabetes")} -> Diabetes
A35: Id1028 | B35: 33.725 | C35: 5.51 | D35: YES | E35: NO | F35: NO | G35: 2 | H35: NO | I35: =IF(G35="No major surgery",0,G35) -> 2 | J35: {=_xlfn.IFS(B35<18.5,"Under Weight",B35<=24.9,"Normal Weight",B35<=29.999,"Over Weight",B35>=30,"Obesity")} -> Obesity | K35: {=_xlfn.IFS(C35<5.7,"Normal",C35<=6.4,"Prediabetes",C35>6.4,"Diabetes")} -> Normal
A36: Id1029 | B36: 28.1 | C36: 11.2 | D36: NO | E36: NO | F36: NO | G36: No major surgery | H36: NO | I36: =IF(G36="No major surgery",0,G36) -> 0 | J36: {=_xlfn.IFS(B36<18.5,"Under Weight",B36<=24.9,"Normal Weight",B36<=29.999,"Over Weight",B36>=30,"Obesity")} -> Over Weight | K36: {=_xlfn.IFS(C36<5.7,"Normal",C36<=6.4,"Prediabetes",C36>6.4,"Diabetes")} -> Diabetes
A37: Id103 | B37: 49.48 | C37: 4.96 | D37: NO | E37: NO | F37: YES | G37: 1 | H37: YES | I37: =IF(G37="No major surgery",0,G37) -> 1 | J37: {=_xlfn.IFS(B37<18.5,"Under Weight",B37<=24.9,"Normal Weight",B37<=29.999,"Over Weight",B37>=30,"Obesity")} -> Obesity | K37: {=_xlfn.IFS(C37<5.7,"Normal",C37<=6.4,"Prediabetes",C37>6.4,"Diabetes")} -> Normal
A38: Id1030 | B38: 37.43 | C38: 4.35 | D38: YES | E38: NO | F38: YES | G38: 1 | H38: NO | I38: =IF(G38="No major surgery",0,G38) -> 1 | J38: {=_xlfn.IFS(B38<18.5,"Under Weight",B38<=24.9,"Normal Weight",B38<=29.999,"Over Weight",B38>=30,"Obesity")} -> Obesity | K38: {=_xlfn.IFS(C38<5.7,"Normal",C38<=6.4,"Prediabetes",C38>6.4,"Diabetes")} -> Normal
A39: Id1031 | B39: 23.7 | C39: 10.45 | D39: NO | E39: NO | F39: NO | G39: No major surgery | H39: NO | I39: =IF(G39="No major surgery",0,G39) -> 0 | J39: {=_xlfn.IFS(B39<18.5,"Under Weight",B39<=24.9,"Normal Weight",B39<=29.999,"Over Weight",B39>=30,"Obesity")} -> Normal Weight | K39: {=_xlfn.IFS(C39<5.7,"Normal",C39<=6.4,"Prediabetes",C39>6.4,"Diabetes")} -> Diabetes
A40: Id1032 | B40: 24.795 | C40: 4.07 | D40: YES | E40: NO | F40: YES | G40: 1 | H40: NO | I40: =IF(G40="No major surgery",0,G40) -> 1 | J40: {=_xlfn.IFS(B40<18.5,"Under Weight",B40<=24.9,"Normal Weight",B40<=29.999,"Over Weight",B40>=30,"Obesity")} -> Normal Weight | K40: {=_xlfn.IFS(C40<5.7,"Normal",C40<=6.4,"Prediabetes",C40>6.4,"Diabetes")} -> Normal
...

Sheet Cleaned Hospitalisation data
A1: Customer ID2 | B1: Children | C1: charges | D1: Hospital Tier | E1: City Tier | F1: State ID | G1: Date Of Birth | H1: Customer Age | I1: Impute Missing Year | J1: Missing Month | K1: date
A2: Id1 | B2: 0 | C2: 63770.43 | D2: Tier - 1 | E2: Tier - 3 | F2: R1013 | G2: 25123 | H2: =INT(YEARFRAC(G2,"8-jun-2023")) -> 54 | I2: 2004 | J2: Nov | K2: 6 | M2: REMOVED ROWS
A3: Id10 | B3: 0 | C3: 48885.14 | D3: Tier - 1 | E3: Tier - 2 | F3: R1013 | G3: 28853 | H3: =INT(YEARFRAC(G3,"8-jun-2023")) -> 44 | I3: 1999 | J3: Jun | K3: 9
A4: Id100 | B4: 2 | C4: 40284.38 | D4: Tier - 1 | E4: Tier - 3 | F4: R1012 | G4: 28303 | H4: =INT(YEARFRAC(G4,"8-jun-2023")) -> 45 | I4: 1985 | J4: Dec | K4: 20 | M4: id2444 | N4: 2 | O4: 20984.09 | P4: Tier - 2 | Q4: Tier - 2 | R4: R1015 | S4: 27-Nov-1987 | T4: =INT(YEARFRAC(S4,"8-jun-2023")) -> 35 | U4: 1970 | V4: Dec | W4: 28
A5: Id1000 | B5: 3 | C5: 11250.43 | D5: Tier - 3 | E5: Tier - 2 | F5: R1026 | G5: 32859 | H5: =INT(YEARFRAC(G5,"8-jun-2023")) -> 33 | I5: 2000 | J5: Oct | K5: 13 | M5: id3444 | N5: 2 | O5: 34303.17 | P5: Tier - 1 | Q5: Tier - 3 | R5: R1013 | S5: 1-Nov-2004 | T5: =INT(YEARFRAC(S5,"8-jun-2023")) -> 18 | U5: 1985 | V5: Sep | W5: 30
A6: Id1001 | B6: 2 | C6: 11244.38 | D6: Tier - 3 | E6: Tier - 1 | F6: R1016 | G6: 25567 | H6: =INT(YEARFRAC(G6,"8-jun-2023")) -> 53 | I6: 1992 | J6: Oct | K6: 6 | M6: Unknown | N6: 0 | O6: 1137.01 | P6: Tier - 3 | Q6: Tier - 1 | R6: R1013 | S6: 38297 | T6: =INT(YEARFRAC(S6,"8-jun-2023")) -> 18 | U6: 1967 | V6: Jun | W6: 14
A7: Id1002 | B7: 2 | C7: 11217.35 | D7: Tier - 3 | E7: Tier - 2 | F7: R1025 | G7: 27939 | H7: =INT(YEARFRAC(G7,"8-jun-2023")) -> 46 | I7: 1991 | J7: Nov | K7: 22 | M7: Unknown | N7: 1 | O7: 2775.19 | P7: Tier - 2 | Q7: Tier - 1 | R7: R1012 | S7: 36320 | T7: =INT(YEARFRAC(S7,"8-jun-2023")) -> 23 | U7: 2004 | V7: Oct | W7: 4
A8: Id1003 | B8: 2 | C8: 11187.66 | D8: Tier - 3 | E8: Tier - 2 | F8: R1012 | G8: 25733 | H8: =INT(YEARFRAC(G8,"8-jun-2023")) -> 52 | I8: 1968 | J8: Oct | K8: 12 | M8: Unknown | N8: 2 | O8: 6203.9 | P8: Tier - 1 | Q8: Tier - 2 | R8: R1012 | S8: 31401 | T8: =INT(YEARFRAC(S8,"8-jun-2023")) -> 37 | U8: 1971 | V8: Dec | W8: 26
A9: Id1004 | B9: 0 | C9: 11186.2 | D9: Tier - 3 | E9: Tier - 2 | F9: R1021 | G9: 26545 | H9: =INT(YEARFRAC(G9,"8-jun-2023")) -> 50 | I9: 1978 | J9: Dec | K9: 29 | M9: Unknown | N9: 0 | O9: 35585.58 | P9: Tier - 1 | Q9: Tier - 2 | R9: R1011 | S9: 36812 | T9: =INT(YEARFRAC(S9,"8-jun-2023")) -> 22 | U9: 1969 | V9: Oct | W9: 11
A10: Id1005 | B10: 0 | C10: 11165.42 | D10: Tier - 3 | E10: Tier - 1 | F10: R1016 | G10: 6-Aug-1966 | H10: =INT(YEARFRAC(G10,"8-jun-2023")) -> 56 | I10: 1977 | J10: Jun | K10: 27 | M10: Unknown | N10: 0 | O10: 36837.47 | P10: Tier - 1 | Q10: Tier - 2 | R10: R1011 | S10: 33883 | T10: =INT(YEARFRAC(S10,"8-jun-2023")) -> 30 | U10: 1981 | V10: Oct | W10: 2
A11: Id1006 | B11: 2 | C11: 11163.57 | D11: Tier - 3 | E11: Tier - 2 | F11: R1011 | G11: 25379 | H11: =INT(YEARFRAC(G11,"8-jun-2023")) -> 53 | I11: 1989 | J11: Dec | K11: 17 | M11: Unknown | N11: 2 | O11: 38711 | P11: Tier - 1 | Q11: Tier - 3 | R11: R1011 | S11: 33564 | T11: =INT(YEARFRAC(S11,"8-jun-2023")) -> 31 | U11: 1969 | V11: Aug | W11: 20
A12: Id1007 | B12: 2 | C12: 11150.78 | D12: Tier - 3 | E12: Tier - 2 | F12: R1011 | G12: 30-Nov-1969 | H12: =INT(YEARFRAC(G12,"8-jun-2023")) -> 53 | I12: 1969 | J12: Dec | K12: 30
A13: Id1008 | B13: 2 | C13: 11103.33 | D13: Tier - 3 | E13: Tier - 1 | F13: R1021 | G13: 20-Aug-1980 | H13: =INT(YEARFRAC(G13,"8-jun-2023")) -> 42 | I13: 1976 | J13: Jun | K13: 28
A14: Id1009 | B14: 0 | C14: 11093.62 | D14: Tier - 3 | E14: Tier - 1 | F14: R1013 | G14: 5-Jul-1966 | H14: =INT(YEARFRAC(G14,"8-jun-2023")) -> 56 | I14: 1970 | J14: Jun | K14: 14
A15: Id101 | B15: 1 | C15: 40273.65 | D15: Tier - 1 | E15: Tier - 3 | F15: R1013 | G15: 29863 | H15: =INT(YEARFRAC(G15,"8-jun-2023")) -> 41 | I15: 1972 | J15: Sep | K15: 3
A16: Id1010 | B16: 0 | C16: 11090.72 | D16: Tier - 3 | E16: Tier - 1 | F16: R1013 | G16: 24359 | H16: =INT(YEARFRAC(G16,"8-jun-2023")) -> 56 | I16: 1966 | J16: Aug | K16: 6
A17: Id1011 | B17: 3 | C17: 11085.59 | D17: Tier - 3 | E17: Tier - 2 | F17: R1012 | G17: 7-Oct-1972 | H17: =INT(YEARFRAC(G17,"8-jun-2023")) -> 50 | I17: 1969 | J17: Jun | K17: 25
A18: Id1012 | B18: 0 | C18: 11082.58 | D18: Tier - 3 | E18: Tier - 2 | F18: R1012 | G18: 24719 | H18: =INT(YEARFRAC(G18,"8-jun-2023")) -> 55 | I18: 1969 | J18: Nov | K18: 30
A19: Id1013 | B19: 0 | C19: 11073.18 | D19: Tier - 3 | E19: Tier - 3 | F19: R1011 | G19: 24431 | H19: =INT(YEARFRAC(G19,"8-jun-2023")) -> 56 | I19: 1980 | J19: Aug | K19: 20
A20: Id1014 | B20: 0 | C20: 11070.54 | D20: Tier - 3 | E20: Tier - 3 | F20: R1011 | G20: 24418 | H20: =INT(YEARFRAC(G20,"8-jun-2023")) -> 56 | I20: 1966 | J20: Jul | K20: 5
A21: Id1015 | B21: 0 | C21: 11068.77 | D21: Tier - 3 | E21: Tier - 2 | F21: R1012 | G21: 9-Nov-1971 | H21: =INT(YEARFRAC(G21,"8-jun-2023")) -> 51 | I21: 1981 | J21: Oct | K21: 4
A22: Id1016 | B22: 0 | C22: 11068.7 | D22: Tier - 3 | E22: Tier - 1 | F22: R1011 | G22: 36787 | H22: =INT(YEARFRAC(G22,"8-jun-2023")) -> 22 | I22: 1966 | J22: Sep | K22: 9
A23: Id1017 | B23: 0 | C23: 11046.02 | D23: Tier - 3 | E23: Tier - 1 | F23: R1026 | G23: 37242 | H23: =INT(YEARFRAC(G23,"8-jun-2023")) -> 21 | I23: 1972 | J23: Oct | K23: 7
A24: Id1018 | B24: 0 | C24: 11037.85 | D24: Tier - 3 | E24: Tier - 2 | F24: R1025 | G24: 30-Aug-1974 | H24: =INT(YEARFRAC(G24,"8-jun-2023")) -> 48 | I24: 1967 | J24: Sep | K24: 4
A25: Id1019 | B25: 3 | C25: 11037.51 | D25: Tier - 3 | E25: Tier - 1 | F25: R1012 | G25: 25-Oct-1989 | H25: =INT(YEARFRAC(G25,"8-jun-2023")) -> 33 | I25: 1966 | J25: Nov | K25: 20
A26: Id102 | B26: 1 | C26: 40208.56 | D26: Tier - 1 | E26: Tier - 2 | F26: R1011 | G26: 28-Jul-1981 | H26: =INT(YEARFRAC(G26,"8-jun-2023")) -> 41 | I26: 1966 | J26: Nov | K26: 7
A27: Id1020 | B27: 4 | C27: 11033.66 | D27: Tier - 3 | E27: Tier - 3 | F27: R1012 | G27: 10-Dec-1974 | H27: =INT(YEARFRAC(G27,"8-jun-2023")) -> 48 | I27: 1971 | J27: Nov | K27: 9
A28: Id1021 | B28: 0 | C28: 11028.56 | D28: Tier - 3 | E28: Tier - 3 | F28: R1012 | G28: 21-Jul-1996 | H28: =INT(YEARFRAC(G28,"8-jun-2023")) -> 26 | I28: 2000 | J28: Sep | K28: 18
A29: Id1022 | B29: 3 | C29: 11018.05 | D29: Tier - 3 | E29: Tier - 2 | F29: R1012 | G29: 26-Jun-1991 | H29: =INT(YEARFRAC(G29,"8-jun-2023")) -> 31 | I29: 2001 | J29: Dec | K29: 17
A30: Id1023 | B30: 4 | C30: 11015.17 | D30: Tier - 3 | E30: Tier - 1 | F30: R1012 | G30: 15-Dec-1974 | H30: =INT(YEARFRAC(G30,"8-jun-2023")) -> 48 | I30: 1974 | J30: Aug | K30: 30
A31: Id1024 | B31: 2 | C31: 11013.71 | D31: Tier - 3 | E31: Tier - 1 | F31: R1013 | G31: 24-Oct-1968 | H31: =INT(YEARFRAC(G31,"8-jun-2023")) -> 54 | I31: 1989 | J31: Oct | K31: 25
A32: Id1025 | B32: 0 | C32: 10991.58 | D32: Tier - 3 | E32: Tier - 3 | F32: R1012 | G32: 17-Sep-2000 | H32: =INT(YEARFRAC(G32,"8-jun-2023")) -> 22 | I32: 1981 | J32: Jul | K32: 28
A33: Id1026 | B33: 0 | C33: 10982.5 | D33: Tier - 3 | E33: Tier - 3 | F33: R1013 | G33: 18-Dec-1965 | H33: =INT(YEARFRAC(G33,"8-jun-2023")) -> 57 | I33: 1974 | J33: Dec | K33: 10
A34: Id1027 | B34: 4 | C34: 10977.21 | D34: Tier - 3 | E34: Tier - 1 | F34: R1013 | G34: 21-Oct-1973 | H34: =INT(YEARFRAC(G34,"8-jun-2023")) -> 49 | I34: 1996 | J34: Jul | K34: 21
A35: Id1028 | B35: 0 | C35: 10976.25 | D35: Tier - 3 | E35: Tier - 2 | F35: R1012 | G35: 9-Jul-1966 | H35: =INT(YEARFRAC(G35,"8-jun-2023")) -> 56 | I35: 1991 | J35: Jun | K35: 26
... A2327: Id990 | B2327: 1 | C2327: 11305.93 | D2327: Tier - 3 | E2327: Tier - 1 | F2327: R1012 | G2327: 6-Oct-1968 | H2327: =INT(YEARFRAC(G2327,"8-jun-2023")) -> 54 | I2327: 1989 | J2327: Aug | K2327: 19
A2328: Id991 | B2328: 4 | C2328: 11299.34 | D2328: Tier - 3 | E2328: Tier - 2 | F2328: R1011 | G2328: 26567 | H2328: =INT(YEARFRAC(G2328,"8-jun-2023")) -> 50 | I2328: 2002 | J2328: Sep | K2328: 20
A2329: Id992 | B2329: 3 | C2329: 11294.57 | D2329: Tier - 3 | E2329: Tier - 1 | F2329: R1022 | G2329: 14-Nov-1988 | H2329: =INT(YEARFRAC(G2329,"8-jun-2023")) -> 34 | I2329: 1963 | J2329: Jul | K2329: 11
A2330: Id993 | B2330: 3 | C2330: 11289.11 | D2330: Tier - 3 | E2330: Tier - 1 | F2330: R1012 | G2330: 25741 | H2330: =INT(YEARFRAC(G2330,"8-jun-2023")) -> 52 | I2330: 1995 | J2330: Dec | K2330: 10
A2331: Id994 | B2331: 0 | C2331: 11286.54 | D2331: Tier - 3 | E2331: Tier - 3 | F2331: R1024 | G2331: 14-Jun-1967 | H2331: =INT(YEARFRAC(G2331,"8-jun-2023")) -> 55 | I2331: 1963 | J2331: Nov | K2331: 22
...

Sheet Healthcare
A1: Customer ID | B1: Title | C1: First Name | D1: Last Name | E1: Date Of Birth | F1: Customer Age | G1: Children | H1: charges | I1: Hospital Tier | J1: City Tier | K1: State ID | L1: BMI | M1: HBA1C | N1: Heart Issues | O1: Any Transplants | P1: Cancer history | Q1: Smoker | R1: Number Of Major Surgeries | S1: Weight Status | T1: Diabetes Status
A2: Id1 | B2: =VLOOKUP(A2,'Customer Names'!$A:$G,7,0) -> Ms | C2: =VLOOKUP(A2,'Customer Names'!$A:$F,6,0) -> Kelly | D2: =VLOOKUP(A2,'Customer Names'!$A:$E,5,0) -> Hawks | E2: =VLOOKUP(A2,'Cleaned Hospitalisation data'!$A:$K,7,0) -> 25123 | F2: =VLOOKUP(A2,'Cleaned Hospitalisation data'!$A$1:$K$2336,8,0) -> 54 | G2: =VLOOKUP(A2,'Cleaned Hospitalisation data'!$A:$K,2,0) -> 0 | H2: =VLOOKUP(A2,'Cleaned Hospitalisation data'!$A$1:$K$2336,3,0) -> 63770.43 | I2: =VLOOKUP(A2,'Cleaned Hospitalisation data'!$A$1:$K$2336,4,0) -> Tier - 1 | J2: =VLOOKUP(A2,'Cleaned Hospitalisation data'!$A$1:$K$2336,5,0) -> Tier - 3 | K2: =VLOOKUP(A2,'Cleaned Hospitalisation data'!$A$1:$K$2336,6,0) -> R1013 | L2: {=_xlfn.XLOOKUP(A2,$A:$A,'Cleaned Medical Examiation data'!$B:$F)} -> 47.41 | M2: 7.47 | N2: NO | O2: NO | P2: NO | Q2: {=_xlfn.XLOOKUP(A2,$A:$A,'Cleaned Medical Examiation data'!$H:$K)} -> YES | R2: 0 | S2: Obesity | T2: Diabetes
A3: Id10 | B3: =VLOOKUP(A3,'Customer Names'!$A:$G,7,0) -> Ms | C3: =VLOOKUP(A3,'Customer Names'!$A:$F,6,0) -> Brooke N | D3: =VLOOKUP(A3,'Customer Names'!$A:$E,5,0) -> Benner | E3: =VLOOKUP(A3,'Cleaned Hospitalisation data'!$A:$K,7,0) -> 28853 | F3: =VLOOKUP(A3,'Cleaned Hospitalisation data'!$A$1:$K$2336,8,0) -> 44 | G3: =VLOOKUP(A3,'Cleaned Hospitalisation data'!$A:$K,2,0) -> 0 | H3: =VLOOKUP(A3,'Cleaned Hospitalisation data'!$A$1:$K$2336,3,0) -> 48885.14 | I3: =VLOOKUP(A3,'Cleaned Hospitalisation data'!$A$1:$K$2336,4,0) -> Tier - 1 | J3: =VLOOKUP(A3,'Cleaned Hospitalisation data'!$A$1:$K$2336,5,0) -> Tier - 2 | K3: =VLOOKUP(A3,'Cleaned Hospitalisation data'!$A$1:$K$2336,6,0) -> R1013 | L3: {=_xlfn.XLOOKUP(A3,$A:$A,'Cleaned Medical Examiation data'!$B:$F)} -> 38.06 | M3: 10.79 | N3: NO | O3: NO | P3: NO | Q3: {=_xlfn.XLOOKUP(A3,$A:$A,'Cleaned Medical Examiation data'!$H:$K)} -> YES | R3: 0 | S3: Obesity | T3: Diabetes
A4: Id100 | B4: =VLOOKUP(A4,'Customer Names'!$A:$G,7,0) -> Mr | C4: =VLOOKUP(A4,'Customer Names'!$A:$F,6,0) -> Daniel | D4: =VLOOKUP(A4,'Customer Names'!$A:$E,5,0) -> Gollins | E4: =VLOOKUP(A4,'Cleaned Hospitalisation data'!$A:$K,7,0) -> 28303 | F4: =VLOOKUP(A4,'Cleaned Hospitalisation data'!$A$1:$K$2336,8,0) -> 45 | G4: =VLOOKUP(A4,'Cleaned Hospitalisation data'!$A:$K,2,0) -> 2 | H4: =VLOOKUP(A4,'Cleaned Hospitalisation data'!$A$1:$K$2336,3,0) -> 40284.38 | I4: =VLOOKUP(A4,'Cleaned Hospitalisation data'!$A$1:$K$2336,4,0) -> Tier - 1 | J4: =VLOOKUP(A4,'Cleaned Hospitalisation data'!$A$1:$K$2336,5,0) -> Tier - 3 | K4: =VLOOKUP(A4,'Cleaned Hospitalisation data'!$A$1:$K$2336,6,0) -> R1012 | L4: {=_xlfn.XLOOKUP(A4,$A:$A,'Cleaned Medical Examiation data'!$B:$F)} -> 48.2 | M4: 4.84 | N4: NO | O4: NO | P4: NO | Q4: {=_xlfn.XLOOKUP(A4,$A:$A,'Cleaned Medical Examiation data'!$H:$K)} -> YES | R4: 0 | S4: Obesity | T4: Normal
A5: Id1000 | B5: =VLOOKUP(A5,'Customer Names'!$A:$G,7,0) -> Mrs | C5: =VLOOKUP(A5,'Customer Names'!$A:$F,6,0) -> Stephanie A | D5: =VLOOKUP(A5,'Customer Names'!$A:$E,5,0) -> Schaefer | E5: =VLOOKUP(A5,'Cleaned Hospitalisation data'!$A:$K,7,0) -> 32859 | F5: =VLOOKUP(A5,'Cleaned Hospitalisation data'!$A$1:$K$2336,8,0) -> 33 | G5: =VLOOKUP(A5,'Cleaned Hospitalisation data'!$A:$K,2,0) -> 3 | H5: =VLOOKUP(A5,'Cleaned Hospitalisation data'!$A$1:$K$2336,3,0) -> 11250.43 | I5: =VLOOKUP(A5,'Cleaned Hospitalisation data'!$A$1:$K$2336,4,0) -> Tier - 3 | J5: =VLOOKUP(A5,'Cleaned Hospitalisation data'!$A$1:$K$2336,5,0) -> Tier - 2 | K5: =VLOOKUP(A5,'Cleaned Hospitalisation data'!$A$1:$K$2336,6,0) -> R1026 | L5: {=_xlfn.XLOOKUP(A5,$A:$A,'Cleaned Medical Examiation data'!$B:$F)} -> 39.17 | M5: 4.15 | N5: NO | O5: NO | P5: NO | Q5: {=_xlfn.XLOOKUP(A5,$A:$A,'Cleaned Medical Examiation data'!$H:$K)} -> NO | R5: 0 | S5: Obesity | T5: Normal
A6: Id1001 | B6: =VLOOKUP(A6,'Customer Names'!$A:$G,7,0) -> Mr | C6: =VLOOKUP(A6,'Customer Names'!$A:$F,6,0) -> Patrick | D6: =VLOOKUP(A6,'Customer Names'!$A:$E,5,0) -> D'Alessandro | E6: =VLOOKUP(A6,'Cleaned Hospitalisation data'!$A:$K,7,0) -> 25567 | F6: =VLOOKUP(A6,'Cleaned Hospitalisation data'!$A$1:$K$2336,8,0) -> 53 | G6: =VLOOKUP(A6,'Cleaned Hospitalisation data'!$A:$K,2,0) -> 2 | H6: =VLOOKUP(A6,'Cleaned Hospitalisation data'!$A$1:$K$2336,3,0) -> 11244.38 | I6: =VLOOKUP(A6,'Cleaned Hospitalisation data'!$A$1:$K$2336,4,0) -> Tier - 3 | J6: =VLOOKUP(A6,'Cleaned Hospitalisation data'!$A$1:$K$2336,5,0) -> Tier - 1 | K6: =VLOOKUP(A6,'Cleaned Hospitalisation data'!$A$1:$K$2336,6,0) -> R1016 | L6: {=_xlfn.XLOOKUP(A6,$A:$A,'Cleaned Medical Examiation data'!$B:$F)} -> 26.41 | M6: 5.99 | N6: YES | O6: NO | P6: YES | Q6: {=_xlfn.XLOOKUP(A6,$A:$A,'Cleaned Medical Examiation data'!$H:$K)} -> NO | R6: 1 | S6: Over Weight | T6: Prediabetes
A7: Id1002 | B7: =VLOOKUP(A7,'Customer Names'!$A:$G,7,0) -> Mrs | C7: =VLOOKUP(A7,'Customer Names'!$A:$F,6,0) -> Krista | D7: =VLOOKUP(A7,'Customer Names'!$A:$E,5,0) -> Wyss | E7: =VLOOKUP(A7,'Cleaned Hospitalisation data'!$A:$K,7,0) -> 27939 | F7: =VLOOKUP(A7,'Cleaned Hospitalisation data'!$A$1:$K$2336,8,0) -> 46 | G7: =VLOOKUP(A7,'Cleaned Hospitalisation data'!$A:$K,2,0) -> 2 | H7: =VLOOKUP(A7,'Cleaned Hospitalisation data'!$A$1:$K$2336,3,0) -> 11217.35 | I7: =VLOOKUP(A7,'Cleaned Hospitalisation data'!$A$1:$K$2336,4,0) -> Tier - 3 | J7: =VLOOKUP(A7,'Cleaned Hospitalisation data'!$A$1:$K$2336,5,0) -> Tier - 2 | K7: =VLOOKUP(A7,'Cleaned Hospitalisation data'!$A$1:$K$2336,6,0) -> R1025 | L7: {=_xlfn.XLOOKUP(A7,$A:$A,'Cleaned Medical Examiation data'!$B:$F)} -> 30.63 | M7: 5.8 | N7: YES | O7: NO | P7: NO | Q7: {=_xlfn.XLOOKUP(A7,$A:$A,'Cleaned Medical Examiation data'!$H:$K)} -> NO | R7: 0 | S7: Obesity | T7: Prediabetes
A8: Id1003 | B8: =VLOOKUP(A8,'Customer Names'!$A:$G,7,0) -> Ms | C8: =VLOOKUP(A8,'Customer Names'!$A:$F,6,0) -> Jenessa | D8: =VLOOKUP(A8,'Customer Names'!$A:$E,5,0) -> Rose | E8: =VLOOKUP(A8,'Cleaned Hospitalisation data'!$A:$K,7,0) -> 25733 | F8: =VLOOKUP(A8,'Cleaned Hospitalisation data'!$A$1:$K$2336,8,0) -> 52 | G8: =VLOOKUP(A8,'Cleaned Hospitalisation data'!$A:$K,2,0) -> 2 | H8: =VLOOKUP(A8,'Cleaned Hospitalisation data'!$A$1:$K$2336,3,0) -> 11187.66 | I8: =VLOOKUP(A8,'Cleaned Hospitalisation data'!$A$1:$K$2336,4,0) -> Tier - 3 | J8: =VLOOKUP(A8,'Cleaned Hospitalisation data'!$A$1:$K$2336,5,0) -> Tier - 2 | K8: =VLOOKUP(A8,'Cleaned Hospitalisation data'!$A$1:$K$2336,6,0) -> R1012 | L8: {=_xlfn.XLOOKUP(A8,$A:$A,'Cleaned Medical Examiation data'!$B:$F)} -> 31.73 | M8: 7.32 | N8: YES | O8: NO | P8: NO | Q8: {=_xlfn.XLOOKUP(A8,$A:$A,'Cleaned Medical Examiation data'!$H:$K)} -> NO | R8: 2 | S8: Obesity | T8: Diabetes
A9: Id1004 | B9: =VLOOKUP(A9,'Customer Names'!$A:$G,7,0) -> Mr | C9: =VLOOKUP(A9,'Customer Names'!$A:$F,6,0) -> Ryan M | D9: =VLOOKUP(A9,'Customer Names'!$A:$E,5,0) -> Hopper | E9: =VLOOKUP(A9,'Cleaned Hospitalisation data'!$A:$K,7,0) -> 26545 | F9: =VLOOKUP(A9,'Cleaned Hospitalisation data'!$A$1:$K$2336,8,0) -> 50 | G9: =VLOOKUP(A9,'Cleaned Hospitalisation data'!$A:$K,2,0) -> 0 | H9: =VLOOKUP(A9,'Cleaned Hospitalisation data'!$A$1:$K$2336,3,0) -> 11186.2 | I9: =VLOOKUP(A9,'Cleaned Hospitalisation data'!$A$1:$K$2336,4,0) -> Tier - 3 | J9: =VLOOKUP(A9,'Cleaned Hospitalisation data'!$A$1:$K$2336,5,0) -> Tier - 2 | K9: =VLOOKUP(A9,'Cleaned Hospitalisation data'!$A$1:$K$2336,6,0) -> R1021 | L9: {=_xlfn.XLOOKUP(A9,$A:$A,'Cleaned Medical Examiation data'!$B:$F)} -> 30.7 | M9: 5.16 | N9: NO | O9: NO | P9: NO | Q9: {=_xlfn.XLOOKUP(A9,$A:$A,'Cleaned Medical Examiation data'!$H:$K)} -> NO | R9: 2 | S9: Obesity | T9: Normal
A10: Id1005 | B10: =VLOOKUP(A10,'Customer Names'!$A:$G,7,0) -> Mr | C10: =VLOOKUP(A10,'Customer Names'!$A:$F,6,0) -> Thomas | D10: =VLOOKUP(A10,'Customer Names'!$A:$E,5,0) -> Finneran | E10: =VLOOKUP(A10,'Cleaned Hospitalisation data'!$A:$K,7,0) -> 6-Aug-1966 | F10: =VLOOKUP(A10,'Cleaned Hospitalisation data'!$A$1:$K$2336,8,0) -> 56 | G10: =VLOOKUP(A10,'Cleaned Hospitalisation data'!$A:$K,2,0) -> 0 | H10: =VLOOKUP(A10,'Cleaned Hospitalisation data'!$A$1:$K$2336,3,0) -> 11165.42 | I10: =VLOOKUP(A10,'Cleaned Hospitalisation data'!$A$1:$K$2336,4,0) -> Tier - 3 | J10: =VLOOKUP(A10,'Cleaned Hospitalisation data'!$A$1:$K$2336,5,0) -> Tier - 1 | K10: =VLOOKUP(A10,'Cleaned Hospitalisation data'!$A$1:$K$2336,6,0) -> R1016 | L10: {=_xlfn.XLOOKUP(A10,$A:$A,'Cleaned Medical Examiation data'!$B:$F)} -> 25.935 | M10: 5.96 | N10: YES | O10: NO | P10: NO | Q10: {=_xlfn.XLOOKUP(A10,$A:$A,'Cleaned Medical Examiation data'!$H:$K)} -> NO | R10: 2 | S10: Over Weight | T10: Prediabetes
A11: Id1006 | B11: =VLOOKUP(A11,'Customer Names'!$A:$G,7,0) -> Ms | C11: =VLOOKUP(A11,'Customer Names'!$A:$F,6,0) -> Amanda N | D11: =VLOOKUP(A11,'Customer Names'!$A:$E,5,0) -> Basham | E11: =VLOOKUP(A11,'Cleaned Hospitalisation data'!$A:$K,7,0) -> 25379 | F11: =VLOOKUP(A11,'Cleaned Hospitalisation data'!$A$1:$K$2336,8,0) -> 53 | G11: =VLOOKUP(A11,'Cleaned Hospitalisation data'!$A:$K,2,0) -> 2 | H11: =VLOOKUP(A11,'Cleaned Hospitalisation data'!$A$1:$K$2336,3,0) -> 11163.57 | I11: =VLOOKUP(A11,'Cleaned Hospitalisation data'!$A$1:$K$2336,4,0) -> Tier - 3 | J11: =VLOOKUP(A11,'Cleaned Hospitalisation data'!$A$1:$K$2336,5,0) -> Tier - 2 | K11: =VLOOKUP(A11,'Cleaned Hospitalisation data'!$A$1:$K$2336,6,0) -> R1011 | L11: {=_xlfn.XLOOKUP(A11,$A:$A,'Cleaned Medical Examiation data'!$B:$F)} -> 35.9 | M11: 4.85 | N11: YES | O11: NO | P11: YES | Q11: {=_xlfn.XLOOKUP(A11,$A:$A,'Cleaned Medical Examiation data'!$H:$K)} -> NO | R11: 1 | S11: Obesity | T11: Normal
A12: Id1007 | B12: =VLOOKUP(A12,'Customer Names'!$A:$G,7,0) -> Ms | C12: =VLOOKUP(A12,'Customer Names'!$A:$F,6,0) -> Teresa P | D12: =VLOOKUP(A12,'Customer Names'!$A:$E,5,0) -> Inman | E12: =VLOOKUP(A12,'Cleaned Hospitalisation data'!$A:$K,7,0) -> 30-Nov-1969 | F12: =VLOOKUP(A12,'Cleaned Hospitalisation data'!$A$1:$K$2336,8,0) -> 53 | G12: =VLOOKUP(A12,'Cleaned Hospitalisation data'!$A:$K,2,0) -> 2 | H12: =VLOOKUP(A12,'Cleaned Hospitalisation data'!$A$1:$K$2336,3,0) -> 11150.78 | I12: =VLOOKUP(A12,'Cleaned Hospitalisation data'!$A$1:$K$2336,4,0) -> Tier - 3 | J12: =VLOOKUP(A12,'Cleaned Hospitalisation data'!$A$1:$K$2336,5,0) -> Tier - 2 | K12: =VLOOKUP(A12,'Cleaned Hospitalisation data'!$A$1:$K$2336,6,0) -> R1011 | L12: {=_xlfn.XLOOKUP(A12,$A:$A,'Cleaned Medical Examiation data'!$B:$F)} -> 26.7 | M12: 5.09 | N12: YES | O12: NO | P12: YES | Q12: {=_xlfn.XLOOKUP(A12,$A:$A,'Cleaned Medical Examiation data'!$H:$K)} -> NO | R12: 1 | S12: Over Weight | T12: Normal
A13: Id1008 | B13: =VLOOKUP(A13,'Customer Names'!$A:$G,7,0) -> Mr | C13: =VLOOKUP(A13,'Customer Names'!$A:$F,6,0) -> Dorian | D13: =VLOOKUP(A13,'Customer Names'!$A:$E,5,0) -> Oscal | E13: =VLOOKUP(A13,'Cleaned Hospitalisation data'!$A:$K,7,0) -> 20-Aug-1980 | F13: =VLOOKUP(A13,'Cleaned Hospitalisation data'!$A$1:$K$2336,8,0) -> 42 | G13: =VLOOKUP(A13,'Cleaned Hospitalisation data'!$A:$K,2,0) -> 2 | H13: =VLOOKUP(A13,'Cleaned Hospitalisation data'!$A$1:$K$2336,3,0) -> 11103.33 | I13: =VLOOKUP(A13,'Cleaned Hospitalisation data'!$A$1:$K$2336,4,0) -> Tier - 3 | J13: =VLOOKUP(A13,'Cleaned Hospitalisation data'!$A$1:$K$2336,5,0) -> Tier - 1 | K13: =VLOOKUP(A13,'Cleaned Hospitalisation data'!$A$1:$K$2336,6,0) -> R1021 | L13: {=_xlfn.XLOOKUP(A13,$A:$A,'Cleaned Medical Examiation data'!$B:$F)} -> 33.71 | M13: 4.94 | N13: NO | O13: NO | P13: NO | Q13: {=_xlfn.XLOOKUP(A13,$A:$A,'Cleaned Medical Examiation data'!$H:$K)} -> NO | R13: 0 | S13: Obesity | T13: Normal
